Workbook

Sheet config
A1: key | B1: value | C1: help
A2: url | B2: http://koltsegvetes.terezvaros.hu/ | C2: A weboldal leendő URL-je. Keresőoptimalizálásnál és megosztásnál van szerepe.
A3: modules.income | B3: 1 | C3: Bevételek szakasz megjelenítése? (1 = Igen, 0 = Nem) Ha ki van kapcsolva, akkor a költségvetés bemutatása a kiadásokkal indul. Automatikusan ki lesz kapcsolva, ha nincs bevételi adat.
A4: modules.inex | B4: 1 | C4: Mérleg szakasz megjelenítése? (1 = Igen, 0 = Nem) Automatikusan kikapcsol, ha a "modules.income" ki van kapcsolva.
A5: modules.milestones | B5: 1 | C5: Fejlesztések szakasz megjelenítése? (1 = Igen, 0 = Nem)
A6: modules.pub | B6: 1 | C6: Kiadványos szakasz megjelenítése? (1 = Igen, 0 = Nem)
A7: modules.feedback | B7: 1 | C7: Visszajelzés szakasz/gomb megjelenítése? (1 = Igen, 0 = Nem)
A8: modules.social | B8: 1 | C8: Legyenek megosztás gombok? (1 = Igen, 0 = Nem)
A9: modules.map | B9: 0 | C9: Térkép szakasz megjelenítése? (1 = Igen, 0 = Nem)
A10: modules.timeseries-income | B10: 1 | C10: Idősor szakasz megjelenítése? (1 = Igen, 0 = Nem)
A11: modules.timeseries-expense | B11: 1 | C11: Idősor szakasz megjelenítése? (1 = Igen, 0 = Nem)
A12: modules.order | B12: timeseries-expense,timeseries-income,milestones,expense,income,inex,pub,map,feedback | C12: Modulok sorrendje (alapértelmezett: pub,inex,income,expense,timeseries-income,timeseries-expense,milestones,map,feedback)
A14: defaultYear | B14: 2026 | C14: Alapértelmezettként kiválasztott év.
A15: seo.siteName | B15: Terézváros | C15: Böngészőablak címsorának 2. része. A teljes címsor max. 60 karakter lehet.
A16: seo.pageTitle | B16: Költségvetés | C16: Böngészőablak címsorának 2. része. A teljes címsor max. 60 karakter lehet.
A17: seo.ogTitle | B17: Közérthető költségvetés 2026 | C17: Facebook/Twitter megosztáskor az előnézeti kártya címsora.
A18: seo.description | B18: Mire, miből és mennyit költ Terézváros? | C18: Google találatban, ill. Facebook/Twitter megosztáskor az előnézeti kártyában megjelenő leírás. Max. 160 karakter.
A19: social.text | B19: Terézváros költségvetése | C19: Megosztáskor a Twitter bejegyzés szövege, LinkedIn poszt vagy email tárgya.
A20: city | B20: Terézváros | C20: Felső navigációs sáv bal oldalán megjelenő városnév.
A22: navBar.showBanner | B22: 0 | C22: Banner megjelenítése? (1 = Igen, 0 = Nem)
A23: navBar.welcome | B23: Köszöntő | C23: Köszöntő szakaszra mutató link szövege a felső navigációs sávban.
A24: navBar.inex | B24: Költségvetés | C24: Költségvetés szakaszra mutató link szövege a felső navigációs sávban.
A25: navBar.milestones | B25: Fejlesztések | C25: Fejlesztések szakaszra mutató link szövege a felső navigációs sávban.
A26: navBar.map | B26: Térkép | C26: Térkép szakaszra mutató link szövege a felső navigációs sávban.
A27: navBar.moreInfo | B27: A projektről | C27: További információ ablakot előhívó link szövege a felső navigációs sávban.
A28: navBar.bannerText | B28: Megcsinálnád településednek? [Telepítsd a keretrendszert!](http://github.com/k-monitor/onkormanyzati-koltsegvetes-v2) | C28: Banner szövege. Markdown jelölések használhatóak (pl. formázás, linkek).
A30: search.tooShort | B30: Túl rövid keresőkifejezés! | C30: Kereséskor megjelenő szöveg, ha túl rövid a keresőkifejezés.
A31: search.noResults | B31: Nincs találat. | C31: Kereséskor megjelenő szöveg, ha nincs találat.
A32: search.income | B32: Bevételek | C32: Keresési találatban megjelenő link szövege, mely a Bevételek szakaszra mutat.
A33: search.expense | B33: Kiadások | C33: Keresési találatban megjelenő link szövege, mely a Kiadások szakaszra mutat.
A34: search.milestones | B34: Fejlesztések | C34: Keresési találatban megjelenő link szövege, mely a Fejlesztések szakaszra mutat.
A35: search.econ | B35: közgazdasági kategória | C35: Keresési találatban megjelenő szöveg, ha az adott találat egy közgazdasági kategória.
... A48: welcome.role | B48: Terézváros polgármestere | C48: Köszöntő szakaszt aláíró személy tisztsége.
A50: tutorial.K1107 | C50: Hasábokra von. tutorial lépések így szúrhatók be. A 2. oszlopba kell írni a szöveget.
A52: pub.lead | B52: Mélyebbre ásnának az adatokban? Ha a költségvetési tételekhez kapcsolódó konkrét, teljesült költésekről (szerződésekről, támogatásokról, közbeszerzésekről) tájékozódnának, ezt Terézváros honlapján, a közérdekű adatok között találják meg. Itt olvasható leírás arról is, hogyan lehet információhoz jutni közérdekű adatigénylés formájában. | C52: Kiadvány szakasz szövege
A53: pub.url | B53: https://terezvaros.hu/atlathatosag | C53: Kiadvány szakasz gombja erre az URL-re linkel.
A55: moreInfo.title | B55: A projektről | C55: További információ ablak címsora.
A56: moreInfo.text | B56: A K-Monitor és partnerei által fejlesztett eszköz alkalmas az önkormányzati költségvetések terv- és tényadatainak bemutatására a megrendelő önkormányzat által meghatározott részletezettségű bontásban. Az adatokhoz kapcsolva egyes bevételi és kiadási előirányzatok tartalmának ismertetése is lehetővé válik. Az eszköz példákkal és illusztrációkkal érthetővé, átélhetővé teszi az önkormányzatok szerteágazó feladatait olyan állampolgárok számára is, akik kevés ismerettel rendelkeznek a közpénzügyek területén. A terézvárosi vizualizáció alapjául szolgáló költségvetések táblázatos formában [itt érhetők el](https://terezvaros.hu/atlathatosag/koltsegvetesek). | C56: További információ ablak címsora. Markdown jelölések használhatóak (pl. formázás, linkek).
A58: inex.title | B58: Mérleg | C58: Mérleg szakasz címsora.
A59: inex.subtitle | B59: Terézváros idei költségvetése: | C59: Mérleg ábra fejléce.
...

Sheet tooltips 2020
A1: Azon. | B1: Megnevezés | C1: Súgószöveg
A2: B1 | B2: Működési célú támogatások államháztartáson belülről | C2: Döntően a központi költségvetésből kapott, normatív alapon járó feladatfinanszírozási és kiegészítő támogatások.
A3: B11 | B3: Önkormányzatok működési támogatásai | C3: Döntően a központi költségvetésből a napi működés kötelező feladataira kapott, kötött felhasználású támogatások tartoznak ide.
A4: B1101 | B4: Önkormányzatok működésének általános támogatása | C4: A központi költségvetésből az önkormányzatok részére, pl. a hivatal működtetésére, településüzemeltetésre (zöldterület-gazdálkodás, közvilágítás, köztemetők) juttatott feladatalapú támogatás.
A5: B1102 | B5: Önkormányzatok egyes köznevelési feladatainak támogatása | C5: A központi költségvetésből az önkormányzatok egyes köznevelési feladatainak (pl. óvodaműködtetés) támogatására biztosított feladatalapú és kiegészítő támogatások.
A6: B1103 | B6: Önkormányzatok szociális gyermekjóléti és gyermekétkeztetési feladatainak támogatása | C6: A központi költségvetésből az önkormányzatok szociális, gyermekjóléti és gyermekétkeztetési feladatainak (ide értve a bölcsődéket) támogatására biztosított feladatalapú és kiegészítő támogatások.
A7: B1104 | B7: Önkormányzatok kulturális feladatainak támogatása | C7: A központi költségvetésből az önkormányzatok könyvtári, közművelődési és múzeumi feladatainak támogatására biztosított feladatalapú és kiegészítő támogatások.
A8: B12 | B8: Egyéb működési célú támogatások bevételei államháztartáson belülről | C8: A Nemzeti Egészségbiztosítási Alapkezelőtől egészségügyi és szociális feladatok ellátására érkező összeg. Ez az összeg a Terézvárosi Egészségügyi Szolgálat és a Terézvárosi Gondozó Szolgálat bevételeinek egy részét képezi.
A9: B2 | B9: Közhatalmi bevételek | C9: A lakosok és a helyi vállalatok által befizetett helyi adók, díjak, bírságok.
A10: B21 | B10: Vagyoni típusú adók | C10: Építményadóból, telekadóból származó bevételek.
A11: B2101 | B11: Építményadó | C11: Az építményadót a Terézvárosban lévő nem lakás céljára szolgáló épületek, épületrészek után kell fizetni. Rendeltetéstől, hasznosítástól függetlenül valamennyi helyiségre kiterjed az adókötelezettség. Az adó alapját a m2-ben számított hasznos alapterület adja.
A12: B2102 | B12: Telekadó | C12: A telekadót a Terézvárosban lévő telek, azaz épülettel, épületrésszel be nem épített földterület után kell fizetni. A telekadó alapját a telek m2-ben számított területe adja.
... A15: B24 | B15: Idegenforgalmi adó | C15: Helyi adó, amelyet a kerületben eltöltött vendégéjszakák után személyenként kell megfizetni.
A16: B25 | B16: Egyéb közhatalmi bevételek (díjak, bírságok, pótlékok )
A17: B3 | B17: Működési bevételek és átvett pénzeszközök | C17: Olyan működéshez köthető bevételek, amelyek nem tartoznak a támogatások, az adóbevételek közé, és nem értékesítésből származnak (például parkolási bevételek, az üzlethelységek, lakások bérleti díja, járóbeteg-ellátáshoz kapott központi támogatás).
A18: B31 | B18: Nyújtott szolgáltatás ellenértéke | C18: Nyújtott szolgáltatásokért elsősorban a költségvetési szervek tesznek szert bevételre. Így jut bevételhez például a Terézvárosi Egészségügyi Szolgálat a díjköteles egészségügyi szolgáltatásokért.
A19: B32 | B19: Közvetített szolgáltatások ellenértéke | C19: A közvetített szolgáltatásokért jellemzően a Belső-Pesti Tankerületi Központ fizet az önkormányzatnak.
A20: B33 | B20: Tulajdonosi bevételek | C20: Parkolásüzemeltetésből, lakások és helyiségek bérleti díjából, közterülethasználati díjból származó önkormányzati bevételek .
A21: B3301 | B21: Parkolási bevétel a fővárosi területeken | C21: A fővárosi tulajdonú közterületeken is a kerületek üzemeltetik a parkolóhelyeket, de a parkolásból származó bevételek – a kerületi költségek levonása után – a fővárosi önkormányzatot illetik. A kerületnek a feladat ellátásából származó bevétele és kiadása ugyanakkora összeget tesz ki. Ez az összeg a kiadások között is megjelenik.
A22: B3302 | B22: Helyiségbérleti-díj bevétel | C22: Az önkormányzat tulajdonában álló, nem lakáscélú helységek bérbeadásából származó bérleti díjak.
A23: B3303 | B23: Lakásbérleti-díj bevétel | C23: Az önkormányzat tulajdonában álló lakások bérbeadásából származó bérleti díjak.
A24: B3304 | B24: Közterülethasználati díjból származó bevétel
A25: B3305 | B25: Haszonbérlet és egyéb parkolási bevétel | C25: A parkolási bevételek a vagyonkezelő céget illetik, de az önkormányzattal kötött haszonbérleti szerződésnek megfelelően a Vagyonkezelő a bevételből havi 50 millió forint + áfát fizet az önkormányzatnak.
A26: B3306 | B26: Piacüzemeltetésből származó bevétel
A27: B3307 | B27: Egyéb tulajdonnal összefüggő bevétel (víz, csatorna, szemét)
A28: B34 | B28: Ellátási díjak | C28: Bölcsődékben, óvodákban, iskolákban az étkezésért fizetett díjakból származó bevételek. Az étkezésért az azt igénybe vevők kb. 60%-a fizet, a többiek ingyenesen vagy kedvezményesen étkeznek.
A29: B35 | B29: Kiszámlázott általános forgalmi adó | C29: A tulajdonosi bevételek (például helyiség-bérbeadásból származó bevételek) áfája.
A30: B36 | B30: Általános forgalmi adó visszatérítése | C30: Az önkormányzati áfás kiadások után visszaigényelhető összeg (például étkeztetés, közüzemi díjak áfája esetében).
A31: B37 | B31: Kamatbevételek | C31: Az államkötvényben tartott befektetésekből származó kamatbevételek.
A32: B38 | B32: Működési célú átvett átvett pénzeszközök | C32: Járóbeteg-ellátáshoz kapott központi támogatás
A33: B4 | B33: Felhalmozási bevételek, támogatások, átvett pénzeszközök | C33: Ingatlanértékesítésből, fővárosi támogatásból, társasházi kölcsönök visszafizetéséből származó bevételek.
A34: B41 | B34: Felhalmozási célú támogatás államháztartáson belülről | C34: A Fővárostól pályázaton elnyert támogatás összege.
A35: B42 | B35: Felhalmozási bevételek - ingatlanértékesítés | C35: A tervezett ingatlanértékesítésből származó bevételek.
A36: B43 | B36: Felhalmozási célú átvett pénzeszközök | C36: A társasházi kölcsönökből származó visszafizetések.
A37: B5 | B37: Finanszírozási bevételek - maradvány igénybevétele | C37: Az előző évi maradvány összege.
A38: FT1 | B38: Finanszírozási bevétel - maradvány | C38: Az előző évi maradvány összege.
A39: K1 | B39: Személyi juttatások és járulékok | C39: Személyi kiadások és a munkáltató által fizetett járulékaik
... A41: K1101 | B41: Külső személyi juttatások | C41: Feladatot ellátó, nem foglalkoztatotti viszonyban lévő személyek juttatásai
A42: K1102 | B42: Munkaadókat terhelő járulékok és szociális hozzájárulási adó
A43: K12 | B43: Polgármesteri hivatal személyi juttatásai és járulékai | C43: Személyi kiadások és a munkáltató által fizetett járulékaik
...

Sheet tooltips 2021
A1: Azon. | B1: Megnevezés | C1: Súgószöveg
A2: 1 | B2: Általános közszolgáltatások | C2: Az általános közszolgáltatások több, mint fele az önkormányzat vagyonának megőrzéséhez és fejlesztéséhez kapcsolódó kiadások. Jókai tér, Vásárcsarnok felújítása, Aradi utca 22. szám alatti bérház felújítása, iskolák felújítása, Csengery utca teljes körű megújítása. Az általános közszolgáltatások másik része a hivatal és az önkormányzati intézmények működtetése.
A3: 10 | B3: Szociális védelem | C3: A bölcsődei, család- és gyermekjóléti szolgáltatások, segélyek, ellátások, támogatások
A4: 1012 | B4: Fogyatékosság | C4: TERÉZÉNO fenntartása
A5: 101221 | B5: Fogyatékossággal élők nappali ellátása | C5: TERÉZÉNO fenntartása
A6: 1020 | B6: Időskor, demens betegek | C6: TEGOSZ nyugdíjas klubjának fenntartása
A7: 102031 | B7: Idősek nappali ellátása | C7: TEGOSZ nyugdíjas klubjának fenntartása
A8: 1040 | B8: Család és gyermekek | C8: A bölcsődék és a családsegítő központ fenntartása, különböző gyermekvédelmi, család- és gyermekjóléti, családtámogatási ellátások, juttatások
A9: 104012 | B9: Gyermekek átmeneti ellátása
A10: 104031 | B10: Gyermekek bölcsődei ellátása
A11: 104035 | B11: Gyermekétkeztetés bölcsődében, fogyatékossággal élők nappali intézményében
A12: 104036 | B12: Munkahelyi étkeztetés bölcsődében
A13: 104037 | B13: Intézményen kívüli gyermekétkeztetés
A14: 104042 | B14: Család- és gyermekjóléti szolgáltatások
A15: 104043 | B15: Család- és gyermekjóléti központ
A16: 104051 | B16: Gyermekvédelmi pénzbeli és természetbeni ellátások
A17: 1070 | B17: Egyéb szociális kirekesztettség | C17: Terézvárosi Gondozó Szolgálat (TEGOSZ) fenntartása, szociális étkeztetés, házi segítségnyújtás, jelzőrendszeres házi segítségnyújtás
A18: 107051 | B18: Szociális étkeztetés
A19: 107052 | B19: Házi segítségnyújtás
A20: 107053 | B20: Jelzőrendszeres házi segítségnyújtás
A21: 107060 | B21: Egyéb szociális pénzbeli és természetbeni ellátások, támogatások
A22: 111 | B22: Államhatalmi, törvényhozó és végrehajtó szervezetek | C22: Az önkormányzat és az önkormányzati hivatal jogalkotó és általános igazgatási tevékenysége, ideértve a nemzetiségi önkormányzatok igazgatását is
A23: 11130 | B23: Önkormányzatok és önkormányzati hivatalok jogalkotó és általános igazgatási tevékenysége | C23: A polgármesteri hivatal kiadásai, a képviselők és választott tisztségviselők juttatásai, a polgármesteri tisztséggel összefüggő egyéb kiadások
A24: 112 | B24: Pénzügyi és költségvetési tevékenységek, adózási ügyek
A25: 11220 | B25: Adó-, vám- és jövedéki igazgatás
A26: 133 | B26: Egyéb általános szolgáltatások | C26: Állampolgársági ügyek, kiemelt rendezvények
A27: 13350 | B27: Az önkormányzati vagyonnal való gazdálkodással kapcsolatos feladatok
A28: 180 | B28: Általános jellegű transzferek a kormányzat különböző szintjei között
A29: 18020 | B29: Központi költségvetési befizetések | C29: A szolidaritási hozzájárulási adó befizetése
A30: 3 | B30: Közrend és közbiztonság | C30: Városrendészet működtetésének költségei, térfigyelőkamera-rendszer fejlesztése és üzemeltetése
A31: 310 | B31: Rendészeti tevékenységek | C31: Városrendészet működtetésének költségei, térfigyelő kamerarendszer fejlesztése és üzemeltetése
A32: 31030 | B32: Közterület rendjének fenntartása | C32: Városrendészet működtetésének költségei, térfigyelő kamerarendszer fejlesztése és üzemeltetése
A33: 4 | B33: Gazdasági ügyek | C33: Közterületek takarításának költségei, közutak, járdák felújítása és fenntartása, vásárcsarnok és piac üzemeltetése, hatósági állatorvosi feladatok ellátása
A34: 411 | B34: Általános gazdasági és kereskedelmi ügyek | C34: Zajmérési vizsgálatok
A35: 41170 | B35: Műszaki vizsgálat, elemzés | C35: Zajmérési vizsgálatok
A36: 412 | B36: Általános munkaügyek | C36: Közterületek takarításának költségei
A37: 41233 | B37: Hosszabb időtartamú közfoglalkoztatás | C37: Közterületek takarításának költségei
A38: 421 | B38: Mezőgazdaság | C38: Hatósági állatorvosi feladatok ellátása
A39: 42180 | B39: Állategészségügy | C39: Hatósági állatorvosi feladatok ellátása
A40: 451 | B40: Közúti közlekedés | C40: Közutak, járdák felújítása és fenntartása
...

Sheet tooltips 2022
A1: Azon. | B1: Megnevezés | C1: Súgószöveg
A2: 1 | B2: Általános közszolgáltatások | C2: Az általános közszolgáltatások több, mint fele az önkormányzat vagyonának megőrzéséhez és fejlesztéséhez kapcsolódó kiadások, illetve a hivatal és az önkormányzati intézmények működtetése, döntéshozatala, igazgatása.
A3: 10 | B3: Szociális védelem | C3: A bölcsődei, család- és gyermekjóléti szolgáltatások, segélyek, ellátások, támogatások.
A4: 1012 | B4: Fogyatékosság | C4: TERÉZÉNO fenntartása
A5: 101221 | B5: Fogyatékossággal élők nappali ellátása | C5: TERÉZÉNO fenntartása
A6: 1020 | B6: Időskor, demens betegek | C6: TEGOSZ nyugdíjas klubjának fenntartása
A7: 102031 | B7: Idősek nappali ellátása | C7: TEGOSZ nyugdíjas klubjának fenntartása
A8: 1040 | B8: Család és gyermekek | C8: A bölcsődék és a családsegítő központ fenntartása, különböző gyermekvédelmi, család- és gyermekjóléti, családtámogatási ellátások, juttatások.
A9: 104012 | B9: Gyermekek átmeneti ellátása | C9: Terézvárosi Család- és Gyermekjóléti Központ tevékenysége.
A10: 104030 | B10: Gyermekek napközbeni ellátása
A11: 104031 | B11: Gyermekek bölcsődei ellátása
A12: 104035 | B12: Gyermekétkeztetés bölcsődében, fogyatékosok nappali intézményében
A13: 104036 | B13: Munkahelyi étkeztetés bölcsődében
A14: 104037 | B14: Intézményen kívüli gyermekétkeztetés
A15: 104042 | B15: Család és gyermekjóléti szolgáltatások
A16: 104043 | B16: Család és gyermekjóléti központ
A17: 1070 | B17: Egyéb szociális kirekesztettség | C17: Terézvárosi Gondozó Szolgálat (TEGOSZ) fenntartása, szociális étkeztetés, házi segítségnyújtás, jelzőrendszeres házi segítségnyújtás
A18: 107051 | B18: Szociális étkeztetés
A19: 107052 | B19: Házi segítségnyújtás
A20: 107053 | B20: Jelzőrendszeres házi segítségnyújtás
A21: 107054 | B21: Családsegítés
A22: 107060 | B22: Egyéb szociális pénzbeli és természetbeni ellátások, támogatások
A23: 111 | B23: Államhatalmi, törvényhozó és végrehajtó szervezetek | C23: Az önkormányzat és az önkormányzati hivatal jogalkotó és általános igazgatási tevékenysége, ideértve a nemzetiségi önkormányzatok igazgatását is.
A24: 11130 | B24: Önkormányzatok és önkormányzati hivatalok jogalkotó és általános igazgatási tevékenysége | C24: A polgármesteri hivatal kiadásai, a képviselők és választott tisztségviselők juttatásai, a polgármesteri tisztséggel összefüggő egyéb kiadások.
A25: 112 | B25: Pénzügyi és költségvetési tevékenységek, adózási ügyek
A26: 11220 | B26: Adó-, vám- és jövedéki igazgatás | C26: A Hivatal adóügyi osztályának működése.
A27: 133 | B27: Egyéb általános szolgáltatások | C27: Vagyongazdálkodási kiadások, amelyek döntően a Vagyonkezelőhöz kötődnek.
A28: 13350 | B28: Az önkormányzati vagyonnal való gazdálkodással kapcsolatos feladatok | C28: Döntően a Vagyonkezelő Zrt. különböző tevékenységeinek kiadásai (karbantartás, javítás, projektmenedzsment, önkormányzati tulajdon után fizetett közös költség stb.)
A29: 180 | B29: Általános jellegű transzferek a kormányzat különböző szintjei között | C29: A központi költségvetésbe fizetendő szolidaritási adó jelenik meg itt.
A30: 18020 | B30: Központi költségvetési befizetések | C30: A központi költségvetésbe fizetendő szolidaritási adó jelenik meg itt.
A31: 3 | B31: Közrend és közbiztonság | C31: Városrendészet működtetésének költségei, térfigyelőkamera-rendszer fejlesztése és üzemeltetése
A32: 310 | B32: Rendészeti tevékenységek | C32: Városrendészet működtetésének költségei, térfigyelő kamerarendszer fejlesztése és üzemeltetése
A33: 31030 | B33: Közterület rendjének fenntartása | C33: Városrendészet működtetésének költségei, térfigyelő kamerarendszer fejlesztése és üzemeltetése
A34: 4 | B34: Gazdasági ügyek | C34: Közterületek takarításának költségei, közutak, járdák felújítása és fenntartása, vásárcsarnok és piac üzemeltetése, hatósági állatorvosi feladatok ellátása
A35: 411 | B35: Általános gazdasági és kereskedelmi ügyek | C35: Zajmérési vizsgálatok
A36: 41170 | B36: Műszaki vizsgálat, elemzés | C36: Zajmérési vizsgálatok
A37: 412 | B37: Általános munkaügyek | C37: Közterületek takarításának költségei
... A51: 7 | B51: Egészségügy | C51: Az egészségügyi kiadások nagy része a Terézvárosi Egészségügyi Szolgálat (TESZ) működtetése: járóbeteg-ellátás, szakorvosi ellátás, védőnői szolgálat, fogorvosi ellátás.
A52: 721 | B52: Általános orvosi szolgáltatások
A53: 72111 | B53: Háziorvosi alapellátás
...

Sheet tooltips 2023
A1: Azon. | B1: Megnevezés | C1: Súgószöveg
A2: 1 | B2: Általános közszolgáltatások | C2: Az általános közszolgáltatások több, mint fele az önkormányzat vagyonának megőrzéséhez és fejlesztéséhez kapcsolódó kiadások, illetve a hivatal és az önkormányzati intézmények működtetése, döntéshozatala, igazgatása.
A3: 10 | B3: Szociális védelem | C3: A bölcsődei, család- és gyermekjóléti szolgáltatások, segélyek, ellátások, támogatások.
A4: 1011 | B4: Betegség
A5: 101110 | B5: Bentlakásos, nem kórházi ellátás, ápolás
A6: 101121 | B6: Pszichiátriai betegek tartós bentlakásos ellátása
A7: 101122 | B7: Szenvedélybetegek tartós bentlakásos ellátása
A8: 101123 | B8: Pszichiátriai betegek rehabilitációs célú bentlakásos ellátása
A9: 101124 | B9: Szenvedélybetegek rehabilitációs célú bentlakásos ellátása
A10: 101125 | B10: Pszichiátriai betegek rehabilitációs lakóotthoni ellátása
A11: 101126 | B11: Szenvedélybetegek rehabilitációs lakóotthoni ellátása
A12: 101131 | B12: Pszichiátriai betegek átmeneti ellátása
A13: 101132 | B13: Szenvedélybetegek átmeneti ellátása
A14: 101133 | B14: Támogatott lakhatás pszichiátriai betegek részére
A15: 101134 | B15: Támogatott lakhatás szenvedélybetegek részére
... A21: 101150 | B21: Betegséggel kapcsolatos pénzbeli ellátások, támogatások
A22: 1012 | B22: Fogyatékosság | C22: TERÉZÉNO fenntartása
A23: 101211 | B23: Fogyatékossággal élők tartós bentlakásos ellátása
A24: 101212 | B24: Fogyatékossággal élők rehabilitációs célú bentlakásos ellátása
A25: 101213 | B25: Fogyatékossággal élők átmeneti ellátása
A26: 101214 | B26: Támogatott lakhatás fogyatékos személyek részére
A27: 101215 | B27: Fogyatékossággal élők ápoló-gondozó lakóotthoni ellátása
A28: 101216 | B28: Fogyatékossággal élők rehabilitációs célú lakóotthoni ellátása
A29: 101221 | B29: Fogyatékossággal élők nappali ellátása | C29: TERÉZÉNO fenntartása
A30: 101222 | B30: Támogató szolgáltatás fogyatékos személyek részére
A31: 101231 | B31: Fogyatékossággal összefüggő pénzbeli ellátások, támogatások
A32: 101232 | B32: Megváltozott munkaképességgel összefüggő pénzbeli ellátások, támogatások
A33: 101240 | B33: Megváltozott munkaképességű személyek foglalkoztatását elősegítő képzések, támogatások
A34: 101270 | B34: Fogyatékossággal élők társadalmi integrációját és életminőségét segítő programok, támogatások
A35: 1020 | B35: Időskor, demens betegek | C35: TEGOSZ nyugdíjas klubjának fenntartása
A36: 102010 | B36: Nyugdíjbiztosítási szolgáltatások igazgatása
A37: 102023 | B37: Időskorúak tartós bentlakásos ellátása
A38: 102024 | B38: Demens betegek tartós bentlakásos ellátása
A39: 102025 | B39: Időskorúak átmeneti ellátása
A40: 102026 | B40: Demens betegek átmeneti ellátása
A41: 102030 | B41: Idősek, demens betegek nappali ellátása
A42: 102031 | B42: Idősek nappali ellátása | C42: TEGOSZ nyugdíjas klubjának fenntartása
A43: 102032 | B43: Demens betegek nappali ellátása
A44: 102040 | B44: Időskorral összefüggő pénzbeli ellátások
A45: 102050 | B45: Az időskorúak társadalmi integrációját célzó programok
...

Sheet tooltips 2024
A1: Azon. | B1: Megnevezés
A2: 1 | B2: Általános közszolgáltatások | C2: Az általános közszolgáltatások több, mint fele az önkormányzat vagyonának megőrzéséhez és fejlesztéséhez kapcsolódó kiadások, illetve a hivatal és az önkormányzati intézmények működtetése, döntéshozatala, igazgatása.
A3: 10 | B3: Szociális védelem | C3: A bölcsődei, család- és gyermekjóléti szolgáltatások, segélyek, ellátások, támogatások.
A4: 1012 | B4: Fogyatékosság | C4: TERÉZÉNO fenntartása
A5: 101221 | B5: Fogyatékossággal élők nappali ellátása | C5: TERÉZÉNO fenntartása
A6: 1020 | B6: Időskor, demens betegek | C6: TEGOSZ nyugdíjas klubjának fenntartása
A7: 102031 | B7: Idősek nappali ellátása | C7: TEGOSZ nyugdíjas klubjának fenntartása
A8: 1040 | B8: Család és gyermekek | C8: A bölcsődék és a családsegítő központ fenntartása, különböző gyermekvédelmi, család- és gyermekjóléti, családtámogatási ellátások, juttatások.
A9: 104012 | B9: Gyermekek átmeneti ellátása | C9: Terézvárosi Család- és Gyermekjóléti Központ tevékenysége.
A10: 1070 | B10: Egyéb szociális kirekesztettség | C10: Terézvárosi Gondozó Szolgálat (TEGOSZ) fenntartása, szociális étkeztetés, házi segítségnyújtás, jelzőrendszeres házi segítségnyújtás
A11: 111 | B11: Államhatalmi, törvényhozó és végrehajtó szervezetek | C11: Az önkormányzat és az önkormányzati hivatal jogalkotó és általános igazgatási tevékenysége, ideértve a nemzetiségi önkormányzatok igazgatását is.
A12: 11130 | B12: Önkormányzatok és önkormányzati hivatalok jogalkotó és általános igazgatási tevékenysége | C12: A Polgármesteri Hivatal kiadásai, a képviselők és választott tisztségviselők juttatásai, a polgármesteri tisztséggel összefüggő egyéb kiadások.
A13: 11220 | B13: Adó-, vám- és jövedéki igazgatás | C13: A Hivatal adóügyi osztályának működése.
... A27: 42180 | B27: Állat-egészségügy | C27: Hatósági állatorvosi feladatok ellátása
A28: 451 | B28: Közúti közlekedés | C28: Közutak, járdák felújítása és fenntartása
A29: 45160 | B29: Közutak, hidak, alagutak üzemeltetése, fenntartása | C29: Közutak, járdák felújítása és fenntartása
A30: 471 | B30: Elosztó kereskedelem, tárolás, raktározás | C30: Vásárcsarnok és piac üzemeltetése
A31: 47120 | B31: Piac üzemeltetése | C31: Vásárcsarnok és piac üzemeltetése
A32: 6 | B32: Közösségi létesítmények | C32: Társasházak felújítását szolgáló támogatások, városfejlesztéshez, városüzemeltetéshez kapcsolódó kiadások (például parkok, játszóterek fenntartása).
A33: 610 | B33: Lakásépítés | C33: Társasházak felújítását szolgáló támogatások
A34: 61030 | B34: Lakáshoz jutást segítő támogatások | C34: Társasházak felújítását szolgáló támogatások
A35: 660 | B35: Egyéb kommunális feladatok | C35: Városfejlesztéshez, városüzemeltetéshez kapcsolódó kiadások (például parkok, játszóterek fenntartása).
A36: 66010 | B36: Zöldterület-kezelés | C36: A zöldterületek fenntartásának, karbantartásának kiadásai
A37: 66020 | B37: Város-, községgazdálkodási egyéb szolgáltatások | C37: Városfejlesztéshez, városüzemeltetéshez kapcsolódó kiadások (például parkok, játszóterek fenntartása).
A38: 7 | B38: Egészségügy | C38: Az egészségügyi kiadások nagy része a Terézvárosi Egészségügyi Szolgálat (TESZ) működtetése: járóbeteg-ellátás, szakorvosi ellátás, védőnői szolgálat, fogorvosi ellátás.
A39: 8 | B39: Szabadidő | C39: Eötvös10 Kulturális Színtér működtetése, Terézváros magazin fenntartása és egyéb lakossági tájékoztatási feladatok ellátása, civil és egyházi szervezetek támogatása, önkormányzat fenntartásában működő siófoki üdülő és dunabogdányi nyári tábor és erdei iskola működtetése.
A40: 810 | B40: Szabadidős és sportszolgáltatások | C40: Önkormányzat fenntartásában működő siófoki üdülő és dunabogdányi nyári tábor és erdei iskola működtetése
... A52: B1 | B52: Működési célú támogatások államháztartáson belülről | C52: Döntően a központi költségvetésből kapott, normatív alapon járó, feladatfinanszírozási és kiegészítő támogatások
A53: B11 | B53: Önkormányzat központi működési támogatásai
A54: B1101 | B54: Önkormányzatok működésének általános támogatása | C54: A központi költségvetésből az önkormányzatok részére, pl. a hivatal működtetésére, településüzemeltetésre (zöldterület-gazdálkodás, közvilágítás, köztemetők) juttatott feladatalapú támogatás
A55: B110101 | B55: Önkormányzati Hivatal működésének állami támogatása
A56: B110102 | B56: Településüzemeltetés - zöldterület-gazdálkodás állami támogatása
A57: B110103 | B57: Településüzemeltetés - közutak állami támogatása
A58: B110104 | B58: Egyéb önkormányzati feladatok állami támogatása
A59: B110105 | B59: A 10 000 lakos feletti önkormányzatok energia áremelkedés miatti támogatása
A60: B1102 | B60: Önkormányzatok egyes köznevelési feladatainak támogatása | C60: A központi költségvetésből az önkormányzatok egyes köznevelési feladatainak, pl. óvodaműködtetés támogatására biztosított feladatalapú és kiegészítő támogatások
A61: B110201 | B61: Óvodaműködtetési támogatás | C61: Központi költségvetésből az óvodák működtetésének támogatása
A62: B110202 | B62: Az óvodákban foglalkoztatott pedagógusok átlagbéralapú támogatása | C62: Központi költségvetésből az óvodák működtetésének támogatása
A63: B110203 | B63: Kiegészítő támogatás a pedagógusok és a pedagógus szakképzettséggel rendelkező segítők minősítéséből adódó többletkiadásokhoz | C63: Központi költségvetésből az óvodák működtetésének támogatása
A64: B110204 | B64: Nemzetiségi pótlék | C64: Központi költségvetésből az óvodák működtetésének támogatása
...

Sheet tooltips 2025
A1: Megnevezés | B1: Azon. | C1: Súgószöveg
A2: Személyi juttatások és járulékok | B2: K1 | C2: =VLOOKUP(B2,'tooltips 2024'!A:C,3) -> Személyi kiadások és a munkáltató által fizetett járulékaik
A3: Önkormányzat személyi juttatásai és járulékai | B3: K11 | C3: =VLOOKUP(B3,'tooltips 2024'!A:C,3) -> Személyi kiadások és a munkáltató által fizetett járulékaik
A4: Külső személyi juttatások | B4: K1102 | C4: =VLOOKUP(B4,'tooltips 2024'!A:C,3) -> Feladatot ellátó, nem foglalkoztatotti viszonyban lévő személyek juttatásai
A5: Munkaadókat terhelő járulékok és szociális hozzájárulási adó | B5: K1103 | C5: =VLOOKUP(B5,'tooltips 2024'!A:C,3)
A6: Polgármesteri Hivatal személyi juttatásai és járulékai | B6: K12 | C6: =VLOOKUP(B6,'tooltips 2024'!A:C,3) -> Személyi kiadások és a munkáltató által fizetett járulékaik
A7: Foglalkoztatottak személyi juttatásai | B7: K1201 | C7: =VLOOKUP(B7,'tooltips 2024'!A:C,3) -> Foglalkoztatotti viszonyban lévők személyi juttatásai.
A8: Külső személyi juttatások | B8: K1202 | C8: =VLOOKUP(B8,'tooltips 2024'!A:C,3) -> Feladatot ellátó, nem foglalkoztatotti viszonyban lévő személyek juttatásai
A9: Munkaadókat terhelő járulékok és szociális hozzájárulási adó | B9: K1203 | C9: =VLOOKUP(B9,'tooltips 2024'!A:C,3)
A10: Óvodák személyi juttatásai és járulékai | B10: K13 | C10: =VLOOKUP(B10,'tooltips 2024'!A:C,3) -> Személyi kiadások és a munkáltató által fizetett járulékaik
A11: Fasori óvoda személyi juttatásai és járulékai | B11: K1301 | C11: =VLOOKUP(B11,'tooltips 2024'!A:C,3) -> Személyi kiadások és a munkáltató által fizetett járulékaik
A12: Foglalkoztatottak személyi juttatásai | B12: K130101 | C12: =VLOOKUP(B12,'tooltips 2024'!A:C,3) -> Foglalkoztatotti viszonyban lévők személyi juttatásai.
A13: Külső személyi juttatások | B13: K130102 | C13: =VLOOKUP(B13,'tooltips 2024'!A:C,3) -> Feladatot ellátó, nem foglalkoztatotti viszonyban lévő személyek juttatásai
... A34: Munkaadókat terhelő járulékok és szociális hozzájárulási adó | B34: K1403 | C34: =VLOOKUP(B34,'tooltips 2024'!A:C,3)
A35: Terézvárosi Értelmi Fogyatékosok Napközi Otthona személyi juttatásai és járulékai | B35: K15
A36: Foglalkoztatottak személyi juttatásai | B36: K1501 | C36: =VLOOKUP(B36,'tooltips 2024'!A:C,3) -> Foglalkoztatotti viszonyban lévők személyi juttatásai.
A37: Külső személyi juttatások | B37: K1502 | C37: =VLOOKUP(B37,'tooltips 2024'!A:C,3) -> Feladatot ellátó, nem foglalkoztatotti viszonyban lévő személyek juttatásai
A38: Munkaadókat terhelő járulékok és szociális hozzájárulási adó | B38: K1503 | C38: =VLOOKUP(B38,'tooltips 2024'!A:C,3)
A39: Terézvárosi Gondozó Szolgálat személyi juttatásai és járulékai | B39: K16
A40: Foglalkoztatottak személyi juttatásai | B40: K1601 | C40: =VLOOKUP(B40,'tooltips 2024'!A:C,3) -> Foglalkoztatotti viszonyban lévők személyi juttatásai.
A41: Külső személyi juttatások | B41: K1602 | C41: =VLOOKUP(B41,'tooltips 2024'!A:C,3) -> Feladatot ellátó, nem foglalkoztatotti viszonyban lévő személyek juttatásai
A42: Munkaadókat terhelő járulékok és szociális hozzájárulási adó | B42: K1603 | C42: =VLOOKUP(B42,'tooltips 2024'!A:C,3)
A43: Terézvárosi Család- és Gyermekjóléti Központ személyi juttatásai és járulékai | B43: K17
A44: Foglalkoztatottak személyi juttatásai | B44: K1701 | C44: =VLOOKUP(B44,'tooltips 2024'!A:C,3) -> Foglalkoztatotti viszonyban lévők személyi juttatásai.
A45: Külső személyi juttatások | B45: K1702 | C45: =VLOOKUP(B45,'tooltips 2024'!A:C,3) -> Feladatot ellátó, nem foglalkoztatotti viszonyban lévő személyek juttatásai
A46: Munkaadókat terhelő járulékok és szociális hozzájárulási adó | B46: K1703 | C46: =VLOOKUP(B46,'tooltips 2024'!A:C,3)
A47: Terézvárosi Egyesített Bölcsődék személyi juttatásai és járulékai | B47: K18
A48: Foglalkoztatottak személyi juttatásai | B48: K1801 | C48: =VLOOKUP(B48,'tooltips 2024'!A:C,3) -> Foglalkoztatotti viszonyban lévők személyi juttatásai.
A49: Külső személyi juttatások | B49: K1802 | C49: =VLOOKUP(B49,'tooltips 2024'!A:C,3) -> Feladatot ellátó, nem foglalkoztatotti viszonyban lévő személyek juttatásai
A50: Munkaadókat terhelő járulékok és szociális hozzájárulási adó | B50: K1803 | C50: =VLOOKUP(B50,'tooltips 2024'!A:C,3)
A51: Dologi kiadások | B51: K2 | C51: =VLOOKUP(B51,'tooltips 2024'!A:C,3) -> A mindennapi működéshez, a feladatok ellátásához szükséges kiadások
A52: Önkormányzat dologi kiadásai | B52: K21 | C52: =VLOOKUP(B52,'tooltips 2024'!A:C,3) -> A mindennapi működéshez, a feladatok ellátásához szükséges kiadások
A53: Készletbeszerzés | B53: K2101 | C53: =VLOOKUP(B53,'tooltips 2024'!A:C,3) -> Működtetéshez szükséges eszközök, például nyomtatványok, irodaszerek beszerzésére fordított összeg
A54: Kommunikációs szolgáltatások | B54: K2102 | C54: =VLOOKUP(B54,'tooltips 2024'!A:C,3) -> Távközlési díjak (internet, telefon), honlapfejlesztés, videókészítés
A55: Szolgáltatási kiadások | B55: K2103 | C55: =VLOOKUP(B55,'tooltips 2024'!A:C,3) -> A dologi kiadások tetemes részét szolgáltatások vásárlására költi az önkormányzat. Ilyenek például: lakóépületek karbantartása, közös költség fizetés, étkeztetés, bérleti jogviszony megváltása
A56: Kiküldetés | B56: K2104
A57: Különféle befizetések és dologi kiadások | B57: K2105 | C57: =VLOOKUP(B57,'tooltips 2024'!A:C,3) -> Legnagyobb tétele az önkormányzat által kifizetett áfa
A58: Polgármesteri Hivatal dologi kiadásai | B58: K22 | C58: =VLOOKUP(B58,'tooltips 2024'!A:C,3) -> A mindennapi működéshez, a feladatok ellátásához szükséges kiadások
A59: Készletbeszerzés | B59: K2201 | C59: =VLOOKUP(B59,'tooltips 2024'!A:C,3) -> Működtetéshez szükséges eszközök, például nyomtatványok, irodaszerek beszerzésére fordított összeg
A60: Kommunikációs szolgáltatások | B60: K2202 | C60: =VLOOKUP(B60,'tooltips 2024'!A:C,3) -> Távközlési díjak (internet, telefon), honlapfejlesztés, videókészítés
...

Sheet milestones
A1: nodeId | B1: year | C1: imageFile | D1: videoFile | E1: title | F1: descriptionInMarkdown | G1: tags | H1: pos | I1: onlyOnMap
B2: 2021 | C2: 2021-1.jpg | E2: Lakossági parkolóhelyeket alakítunk ki | F2: Terézváros önkormányzata a mostani parkolóhelyek közül közel 1400-at hamarosan kizárólagos használatra a VI. kerület lakóinak ad át az esti órákban. A táblával megjelölt helyeken 18 és reggel 7 óra között csak azok a helyi lakosok parkolhatnak majd, akik éves parkolási engedéllyel rendelkeznek. Az intézkedés lényege, hogy munkaidő után a parkolóhelyek a hazatérő terézvárosiak rendelkezésére álljanak. A terézvárosi parkolóhelyek kialakításával egyidőben felülvizsgáljuk a mozgássérült parkolóhelyek és a rakodóhelyek kijelölését is, hogy a speciális várokozóhelyek a valós igényekhez igazodjanak.
B3: 2021 | C3: 2021-2.jpg | E3: Közösségi tereket hozunk létre | F3: A Jókai tér a teljes megújítást követően méltó szomszédja lesz a világörökség részét képező Andrássy útnak. A teret határoló utcákról eltűnik a rossz állapotú macskakő, az új burkolat jóvoltából megszűnik a zaj, könnyebbé válik a közlekedés. A tér új zöldfelületet kap, de átlátható lesz, ez is biztosítja majd a rendet, tisztaságot. A térrel szomszédos utcákban megváltozik a parkolási rend is, azzal a céllal, hogy a gyalogosok biztonságosabban közlekedhessenek. A fővárosi önkormányzat által meghirdetett 2016-os TÉR-KÖZ városrehabilitációs pályázaton Terézváros önkormányzata 200 millió Ft támogatást nyert a tér rendezésére. A Podmaniczky utcai kutyafuttató idei felújítását tavaly már közösségi tervezés, több lakossági egyeztetés előzte meg. Mivel jelenleg ez a kerület egyetlen kutyafuttatója, fontos, hogy a gazdik és a kutyák számára is szép, rendezett, pihenésre alkalmas környezet jöjjön létre. A Rózsa utca 53. szám alatti önkormányzati tulajdonú telken egy ideiglenes közösségi kertet alakítunk ki, ahol a terézvárosiak kertészkedhetnek majd a kialakított parcellákban. A telek így nemcsak kizöldül, hanem fontos közösségi színtere is lehet a beszélgetéseknek, a szabadidő közös és hasznos eltöltésének. A Benczúr utcában pótoljuk a fasor fáit, bokrokat, cserjéket ültetünk, és ezzel párhuzamosan a járdákat is megújítjuk, hogy biztosítsuk ezzel a növények életterét és az akadálymentes közlekedést is. Tárgyalunk a Magyar Képzőművészeti Egyetem vezetésével, hogy a terület rendezésével az Epreskert egy részét megnyithassuk a terézvárosiak számára. _A költségvetésben rendelkezésre álló összegek:_ Jókai tér fejújítása: 510 millió Ft Podmaniczky utcai kutyafuttató megújítása: 15 millió Ft Rózsa utcai közösségi kert létrehozása: 20 millió Ft Benczúr utcai fasor megújítása, zöldsáv kialakítása: 46 millió Ft Epreskert megnyitása: 60 millió Ft
B4: 2021 | C4: 2021-3.jpg | E4: Megújítjuk a külső után a vásárcsarnok belső terét is | F4: Idén új szakaszához ér a Hunyadi téri vásárcsarnok felújítása. Tavaly a közösségi tervezés során megismertük a helyiek igényeit, most ezek alapján elkezdjük a csarnok belső tereinek tervezését. Az a célunk, hogy a belső átépítés figyelembe vegye a Czingler Győző által 1896-ban tervezett, és nemrégiben megújult külsőt. A csarnok tervezett megújításával párhuzamosan a Szófia utca is új szerephez juthat: a csarnokban működő vendéglátók teraszai újfajta pezsgést hozhatnak a környékre. _A költségvetésben rendelkezésre álló összeg:_ Vásárcsarnok felújításának tervezési munkája: 120 millió Ft
B5: 2021 | C5: 2021-4.jpg | E5: Növeljük a bérlakások számát | F5: Terézváros önkormányzata elkötelezett a lakhatási válság csökkentése mellett. A Terézváros otthont ad programban a lakásállomány folyamatos karbantartásával párhuzamosan idén húsz, eddig használaton kívüli önkormányzati bérlakást újítunk fel, ezekbe Terézvárosban élők és dolgozók (szolgálati lakások) költözhetnek majd be. A lakások korszerűsítésével párhuzamosan az Aradi utca 22. szám alatti bérház felújításának első szakasza is elindul, ezzel is tovább növeljük a bérlakásaink számát. Egy teljesen új önkormányzati fenntartású bérlakás-projekt is elindul egy új bérház tervezésének, építésének előkészítésével. _A költségvetésben rendelkezésre álló összegek:_ Húsz bérlakás felújítása: 110 millió Ft Aradi u. 22. - lakóépület felújítása: 265 millió Ft Bérház építésének előkészítése: 30 millió Ft
B6: 2021 | C6: 2021-5.jpg | E6: A Csengery utcában teljes körű megújítást végzünk fásítással | F6: Az önkormányzat már 2020-ban megkezdte a Csengery utca (Aradi és Podmaniczky utca közötti szakasz) teljes megújításának és ezzel párhuzamosan a fásítási munkáinak előkészítését. A tervezést megelőzve elkészült egy tanulmány, amely azt vizsgálta, hogyan lehet fákat ültetni a szűk, közműhálózattal átszőtt utcában. Több megoldási javaslat is született, melyet a lakók már megismerhettek, a végleges tervek is a terézvárosiak véleménye alapján fog megszületni. Az biztos, hogy a Csengery utca amellett, hogy igazi zöldfelületet kap, teljesen meg is újul. Az átalakításnak csak egy kis szelete a fásítás, emellett az utcaszakasz infrastruktúrája is átalakul: nő a járdák mérete, biztonságosabb lesz a közlekedés. _A költségvetésben rendelkezésre álló összeg:_ Közterület-megújítás, a Csengery utca, Aradi és Podmaniczky utca közötti teljes megújítása: 400 millió Ft
B7: 2021 | C7: 2021-6.jpg | E7: Magánberuházókkal közösen szépítjük meg a Paulay utcát | F7: A Paulay és a Hegedű utcában jelenleg egy időben több szálloda is épül. Az önkormányzat a beruházókkal településrendezési szerződést kötött, amelyben az építtetők vállalják, hogy a készülő hotel környékén nemcsak rendezik a keletkezett károkat, hanem rendbe teszik, megszépítik a közterületet. A Paulay utca 52-nél folyó építkezést követően az önkormányzat és a beruházó összefogásával átalakítjuk a terület Nagymező utca és Liszt Ferenc tér közötti részét. Zöld szigeteket alakítunk ki, ezzel is csillapítjuk a Paulay utca forgalmát. Az utcát a későbbiekben teljes hosszában felújítjuk a Hegedű utcával együtt, így élhetőbb, csendesebb, tisztább közterületeket kapnak az ott élők. _A költségvetésben rendelkezésre álló összegek:_ Paulay u., Hegedű u. és Liszt F. tér közötti szakaszán út- és járdaépítés: 30 millió Ft
B8: 2021 | C8: 2021-7.jpg | E8: Korszerűsítjük az egészségügyi és oktatási intézményeket | F8: Megújul idén a Tóth Aladár Zeneiskola és Szinyei Merse Pál Gimnázium Kmetty utcai külső homlokzata. Munkálatok folynak majd a Lendvay utcai Játékvár óvodában is, ahol az udvart újítjuk fel, a Bajza utcai Általános Iskolában pedig a tanuszoda fűtéskorszerűsítét végezzük el. A Terézvárosi Egészségügyi Szolgálat Csengery utcai épületében többek között megújul a hűtő-fűtő rendszer, kicseréljük az elavult gépeket, műszereket részben az Egészséges Budapest Program keretében. A gyermekfogászati rendelőben beléptető- és betegirányító rendszert alakítunk ki. _A költségvetésben rendelkezésre álló összegek:_ Tóth Aladár Zeneiskola homlokzatfelújítása: 100 millió Ft Játékvár óvoda udvarfelújítása: 65 millió Ft Bajza utcai Általános Iskola tanuszodájának fűtéskorszerűsítése: 25 millió Ft Szinyei Merse Pál Gimnázium homlokzatfelújítása: 70,6 millió Ft Terézvárosi Egészségügyi Szolgálat épületfelújítása, műszereinek korszerűsítése: 891 millió Ft
B9: 2021 | C9: 2021-8.jpg | E9: Fejlesztjük a környezetbarát közlekedés lehetőségeit | F9: A környezetbarát közlekedési eszközök népszerűsítése, valamint az elektromos rollerek kulturált elhelyezésének érdekében az önkormányzat a fővárossal közösen, több ütemben mikromobilitási pontokat hoz létre Belső-Terézvárosban. A jórészt forgalomtól elzárt területeken kialakítandó pontokon lehet majd biztonságosan elhelyezni a kerékpárokat, rollereket, robogókat. Ezeken a pontokon lesz az elektromos rollerek kötelező lerakata is. A projekt keretében a főváros a saját kezelésű területein 48, Terézváros önkormányzata pedig 38 ponton alakít ki mobilitási pontot. A mobilitási pontokkal összhangban elektromos töltőállomások kihelyezésének előkészítése is elindult, és új kerékpártámaszok kerülnek ki a kerületben. Hosszú évek problémájának megoldását szolgálja a Bajza és Bulcsú utcát összekötő aluljáró felújítása. A sok tulajdonos között az önkormányzatnak sikerült elérni az együttműködést: a MÁV, a fővárosi önkormányzat, valamint a kerületi önkormányzatok elkezdtek dolgozni a részfeladatokon, a tervek tavaszra készen lesznek, utána kezdődhet a kivitelezés. Az aluljáró megújítása után jelentős szerepet tölt majd be a kerékpáros közlekedési hálózatban. _A költségvetésben rendelkezésre álló összegek:_ Forgalomcsillapítás, mobilitási pontok kialakítása, kerékpártámaszok: 50 millió Ft Bajza-Bulcsú aluljáró megújítása zöldfelületekkel: 56 millió Ft
B10: 2021 | C10: 2021-9.jpg | E10: A koronavírus-járvány költségvetési hatásai | F10: A járvány és a nyomában járó gazdasági válság súlyos következményekkel járt az idegenforgalmáról, vendéglátásáról ismert Terézvárosban. A bezárt éttermek, szállodák, szórakozóhelyek miatt keletkező bevételkiesést azonban jóval meghaladta a kormányzati elvonás, amivel együtt Terézváros önkormányzata csaknem 3 milliárd forint bevételtől esik el. **Kormányzati elvonások:** iparűzési adó: 753 846 000 Ft gépjárműadó elvonása: 115 000 000 Ft központi támogatásként kirótt összeg: 674 326 000 Ft ingyenes parkolásból származó bevételkiesés: 520 000 000 Ft **Járvány gazdasági hatásai:** idegenforgalmi adó elmaradása: 600 000 000 Ft közterület foglalási díjak elmaradása: 200 000 000 Ft **Összesen: 2 863 172 000 Ft** Az elvonások, bevételcsökkenések ellenére is kötelességének érzi az önkormányzat, hogy segítse azokat, akik a járvány miatt kerültek nehéz anyagi helyezte. A Terézváros melléd áll! programmal az állás nélkül maradt magánszemélyek, és a munka nélkül maradt vállalkozások is segítséget kaptak, hogy talpon maradjanak és átvészeljék a nehéz hónapokat. Az önkormányzat szociális programja a diákokat is segíti azzal, hogy biztosítja a számítástechnikai hátteret az online tanuláshoz.
B11: 2022 | C11: 2022-1.jpg | E11: Megújuló, zöldülő utcák | F11: Elkötelezettek vagyunk a környezettudatos, fenntartható városi lét kialakításában, a közterületeink élhetőbbé tételében. Éppen ezért az elmúlt harminc év legnagyobb közterület-fejlesztését készülünk véghezvinni. Idén elkezdjük a Csengery utca megújítását, és további közterületek felújításának tervezését. Részleges vagy teljes utcamegújítás, zöldítés és forgalomcsillapítást készítünk elő a Szondi, a Szinyei Merse Pál, a Felsőerdősor, az Eötvös, a Szófia, a Rózsa, a Németh László, a Szobi, a Kármán, a Lovag, a Dobó, a Káldy Gyula, a Paulay Ede és a Zichy Jenő utcában, a Bajcsy-Zsilinszky és a Révay közben. Ezek tervezésénél az alternatív közlekedési formák, a forgalomcsillapítás, valamint a gyalogos- és zöldfelületek, közösségi terek maximalizálásán lesz a hangsúly. A kerület növényzettel legkevésbé ellátott területein, így a Szondi, a Szinyei Merse Pál, a Vörösmarty, a Csengery és az Eötvös utcában fásítást készítünk elő. Az Andrássy úti műfű korábbi helyére végre igazi, évelő növények kerülnek, amit a világörökségi területhez méltó ráccsal és emelt szegéllyel védünk majd a parkoló autóktól és a kutyavizelettől.
B12: 2022 | C12: 2022-2.jpg | E12: Parkolási káosz enyhítése | F12: Visszaadjuk a terézvárosiaknak a kerületi parkolóhelyek harmadát. Belső-Terézvárosban már használják az este 6 és reggel 7 közötti időtartamra szóló kizárólagos lakossági parkolóhelyeket, idén pedig Külső-Terézvárosban is megtörténik ezek kitáblázása. A kedvezményes parkolási engedéllyel rendelkező lakóknak így ezeken a területeken is könnyebb lesz parkolóhelyhez jutni. Az önkormányzat anyagi hozzájárulásával továbbra is kedvezményes áron juthatnak parkolóházi helyekhez a helyi lakosok. Hét parkolóházban a piaci árhoz képest 60-70 százalékos kedvezménnyel tudnak parkolni azok, akik cserébe lemondanak az éves parkolási engedélyükről. A dugók, a benzingőz mérséklése minden közlekedő érdeke, így ösztönözzük az alternatív közlekedési eszközök használatát. Belső-Terézvárosban 86 helyen építünk ki mikromobilitási pontokat, azaz a kerékpároknak, rollereknek és robogóknak parkolóhelyeket. Itt kell majd kötelezően elhelyezni az elektromos rollereket is, így ezzel megszűntetjük a sokakat bosszantó rollerkáoszt. Elkezdjük az elektromos töltőállomások kialakításának előkészítését is, és új kerékpártámaszokat is telepítünk.
B13: 2022 | C13: 2022-3.jpg | E13: Biztonságosabb és tisztább közterületek | F13: A kerületi térfigyelő rendszer évek óta elavult. Idén elkezdjük a kamerarendszer modernizálását, amelynek köszönhetően a meglévő 95 helyszín mellett további 45-re helyezünk ki új kamerákat. Ezek segítségével a bűncselekményt vagy az illegális szemétlerakást elkövetőkkel szemben is hatékonyabban tudunk fellépni. A helyi rendőrkapitányságot és a Terézváros Közrendjéért és Közbiztonságáért Alapítványt idén is támogatja az önkormányzat. Ahogy a korábbi években, a köztisztaságra továbbra is kiemelt figyelmet fordítunk. A rendszeres és alapos takarításhoz szükséges források biztosítása mellett további új kukák és csikktartók, új kutyaboxok kihelyezésére is sor kerül idén.
... B19: 2022 | C19: 2022-9.jpg | E19: Mire fordítjuk a legtöbbet 2022-ben? | F19: Reménykedünk, hogy 2022 a nyugodtabb építkezés éve lesz, és nem egy újabb koronavírus-járvány vagy egy európai háború határozza meg az életünket. Egy normális évet szeretnénk, amikor az önkormányzat bevételei olyan ütemben nőnek, mint a 2010-es években, mert így egyszerre válna lehetővé a tartalékképzés és a tervezett fejlesztések végrehajtása mellett az újabbak tervezése, a rászorulóknak járó támogatások további bővítése.
B20: 2023 | C20: 2023-1.jpg | E20: Terézváros 2030 - megújuló utcák, terek | F20: A sok egyeztetéssel járó, hosszú tervezési folyamat után idén elkezdjük felszedni az aszfaltot, indulnak a felújítási munkálatok Terézváros utcáin. Ezzel az elmúlt harminc év legnagyobb közterület-megújítási programját kezdjük megvalósítani. Tavasszal rajtol a Csengery utca felújítása, majd nekilátunk a Bajcsy köz, a Szobi és a Káldy Gyula utca, a Révay köz teljes szakaszának, idén kezd szépülni a Szinyei Merse utca, a Paulay utca, vagy éppen a Ferdinánd rézsű, tovább fejlesztjük a Liszt Ferenc teret. A folyamat végére, 2030-ra nem maradhat egyetlen utca és tér sem, amit valamilyen módon ne tennénk emberléptékűbbé, használhatóbbá, tisztábbá és rendezettebbé. A kerületben ugyanis az alternatív közlekedési lehetőségek javításán, a forgalomcsillapításon, a gyalogos- és zöldfelületek növelésén, valamint a közösségi terek maximalizálásán lesz a hangsúly. | G20: 🚧 Fejlesztések, 🧹 Köztisztaság
B21: 2023 | C21: 2023-2.jpg | E21: Könnyebb parkolás, biztonságosabb közlekedés | F21: Az átmenő forgalmat és a vendégparkolások számát csökkenteni, a terézvárosiak parkolását viszont továbbra is könnyíteni szeretnénk. Belső-Terézvárosban tavaly óta használják az este 6 és reggel 7 közötti időtartamra szóló kizárólagos lakossági parkolóhelyeket, ennek előnyeit pedig idén már a Külső-Terézvárosban élők is élvezhetik. A lakossági parkolási engedéllyel rendelkező lakóknak így ezeken a területeken is könnyebb lesz parkolóhelyhez jutni. Az önkormányzat anyagi hozzájárulásával továbbra is jóval piaci ár alatt juthatnak parkolóházi helyekhez – immár 128-hoz – a helyi lakosok. Tavaly hét, idén már kilenc parkolóházban élhetnek ezzel a lehetőséggel azok a terézvárosiak, akik cserébe lemondanak az éves parkolási engedélyükről, azaz a felszíni parkolóhelyek kedvezményes használatáról. A forgalomcsillapítást és a biztonságot növeli, hogy valamennyi átalakuló utcában kiemeljük a kereszteződéseket, helyenként elhúzzuk a sávokat, lassításra kényszerítve ezzel az autósokat. Sőt, ennél is tovább megyünk: azokon a területeken, ahol nem közlekednek a BKV járművei, bevezetjük a 30 kilométer/órás sebességkorlátozást. A terézvárosi és a fővárosi önkormányzat is alakít ki mobilitási pontokat, Mobikat a kerületben, amelyből összesen 105 darab lesz a folyamat végére. Csak itt lehet majd letenni a kölcsönzött e-rollereket, de lehet majd itt parkolni saját kerékpárral vagy rollerrel is. | G21: 🚧 Fejlesztések, 🚦 Közlekedés
B22: 2023 | C22: 2023-3.jpg | E22: Tisztább, biztonságosabb közterületek | F22: A kerület több pontján megújul a közvilágítás, és idén elkészül az a 140 kamerából álló modern térfigyelő-rendszer, amellyel Terézváros teljes területén, a nap 24 órájában nyomon lehet követni minden eseményt. A megújuló kamerarendszer nem csak a rendőrök munkáját, a bűnelkövetők elfogását segíti, hanem az illegális szemetelőket, de akár a kutyaürüléket hátrahagyókat is könnyebben tetten lehet érni. Bár eddig is kiemelkedő összegből gazdálkodhatott, tovább növeltük a köztisztaságért felelős Terézvárosi Foglalkoztatást Elősegítő Nonprofit Kft. költségvetését. A cél ugyanis az, hogy a közterek soha nem látott gyakorisággal való tisztításával, a rendkívüli takarítások mielőbbi elvégzésével mintakerületet teremtsünk. A köztiszta cégünk megnövelt büdzséjéből jut majd például két új, környezetbarát teherautóra, dolgozói létszámbővítésre, szerelőműhely kialakítására, még gyakoribb utcamosásra, újabb kukák és dogboxok kihelyezésére, a zöldfelületek hatékonyabb kezelésére, és olyan gyorsreagálású csoport megszervezésére, amely a köztisztasági panaszok bejelentésekor azonnal intézkedik. Emellett az eddigieknél nagyobb hangsúlyt fektetnek a köztisztasággal kapcsolatos figyelemfelhívásra, tájékoztatásra, szemléletformálásra is. | G22: 🚧 Fejlesztések, 🛡️ Közbiztonság, 🧹 Köztisztaság
B23: 2023 | C23: 2023-4.jpg | E23: Újjászülető társasházak, zöldülő udvarok | F23: A társasházak felújításához évről évre növeljük a pályázható összeg nagyságát, és folyamatosan bővítjük a pályázati palettát, egyre több munkára lehet támogatást nyerni. Emellett Budapest 150. születésnapja apropóján külön homlokzatfelújítási pályázatot is hirdettünk a társasházaknak, amellyel ugyancsak jelentős összegű támogatást kaphatnak a tulajdonosok az épületek megszépítéséhez. Ahogy korábban, idén is támogatást lehet nyerni egyebek mellett a nyílászárók cseréjéhez, kéménybéleléshez, vagy épp a postaládák cseréjéhez. A zöld pályázatokon nyerhető támogatásokkal a társasházak belső udvarait zöld szigetekké alakíthatják a lakók, hiszen új zöld felületek kialakítására, újabb növények telepítésére, növényfalakra, homlokat befuttatására, növényládák beszerzésére és öntözőrendszer kialakítására, továbbá a kertépítészeti tervek kidolgozására, komposztálóra, padok és kerékpártámaszok telepítésére is lehet támogatást nyerni. Térítésmentesen biztosítjuk a társasházaknak, hogy minősített favizsgáló szakember mérje fel az udvarokon lévő fákat, a Terézvárosi Foglalkozást Elősegítő Nonprofit Kft. pedig elvégezze az ápolási és növény-egészségügyi munkákat. Az Utcakert Programmal az ingatlanok előtti közterület zöldítését segítjük. | G23: 🌱 Zöld, 🚧 Fejlesztések
B24: 2023 | C24: 2023-5.jpg | E24: Terézváros otthont ad | F24: Noha folyamatosan hozzuk rendbe a rossz állapotú, lakhatatlan bérlakásokat, és ezekbe folyamatosan költözhetnek be a bérlőink, még mindig sok kerületi lakos küzd lakhatási gondokkal. Éppen ezért idén is folytatjuk az ingatlanjaink lakhatóvá tételét, így a tervek szerint év végére újabb 30 lakással bővül a kiadható állapotban lévő ingatlanjaink száma. Ezekbe a szociális és szolgálati lakásokba lakhatási problémákkal küzdő terézvárosiak és terézvárosi közintézményekben dolgozók költözhetnek be. Az Aradi utca 22. szám alatt lévő, teljes mértékben saját tulajdonú bérházunk teljes, a pincétől a padlásig történő felújítását tavaly elkezdtük, és idén is folytatjuk. Egyebek mellett megerősítjük a ház alapját, hogy a későbbi extra terheket, például az új födémet elbírja, felújítjuk a külső homlokzatot, kicseréljük a liftet, megújítjuk a ház elektromos hálózatát, felújítjuk az utcai üzlethelyiségeket, a tetőtérben pedig egy új lakást alakítunk ki. | G24: ❤️ Gondoskodás, 🚧 Fejlesztések
B25: 2023 | C25: 2023-6.jpg | E25: Jól karbantartott intézmények | F25: Napjuk jelentős részét oktatási-nevelési intézményben töltik a gyerekek, ezért nagy gondot fordítunk ezek minél korszerűbbé, szebbé, használhatóbbá tételére. A kisebb-nagyobb felújítási, karbantartási munkálatok rendszeresek, de idén tervezzük például a Szív Óvoda tetejének átfogó javítását és szigetelését, több helyen pedig fűtéskorszerűsítést, hőszigetelést, nyílászárócserét végzünk; utóbbit például a Városliget fasori bölcsődénkben. Ebben az évben végezzük el a Kincseskert Óvoda teljes udvarfelújítását, ahogy a Játékvár Óvoda udvarának felújítása is folytatódik. Idén kerül sor a Derkovits Gyula Általános Iskola konyhafelújítására, akadálymentesítjük a Szinyei Merse Pál Gimnázium Kmetty utcai bejáratát. A Terézvárosi Egészségügyi Szolgálat állami átvételét nem támogatjuk, és ahogy korábban, idén is dolgozunk a korszerűsítésén. Jelentős összeget fordítunk egyebek mellett a tűzvédelemre, liftekre, tetőfelújításra. | G25: 🚧 Fejlesztések, 🧸 Óvoda, ❤️ Gondoskodás
B26: 2023 | C26: 2023-7.jpg | E26: Elkezdődhet a Hunyadi téri piac belső felújítása | F26: Csakúgy, mint az utcák, a piac belsejének felújítását is hosszú tervezési folyamat előzte meg, amely során a kereskedelmi, a szolgáltatói és a közösségi szempontokra egyaránt figyelmet fordítottunk. Idén pedig már sor kerülhet a közbeszerzés kiírására. Ha ez sikerrel zárul, az év második felében elkezdődhetnek a munkálatok. Ennek során megtörténik az utólagos hozzáépítések elbontása, a belső területek helyreállítása, egy többfunkciós galéria építése. A Szófia utcai oldalra tervezett teraszok, a környező utcák gyalogosbaráttá, élhetőbbé alakítása is hangsúlyos szerepet kapott a tervekben. | G26: 🚧 Fejlesztések, 🚦 Közlekedés
B27: 2023 | C27: 2023-8.jpg | E27: Széleskörű szociális gondoskodás | F27: Mi vagyunk a legszolidárisabb kerület. A ciklus eleje óta minden évben bővítettük a szociális támogatások körét, növeltük egyes támogatások mértékét, így Budapesten immár mi adjuk a legtöbb támogatást, a legnagyobb összegekkel és a legmagasabb felső jövedelemhatárral. Továbbá egy kerület sem támogatja olyan mértékben az iskolai, óvodai étkeztetést, mint mi. Nem csak a támogatásokra, a szociális intézményeinkre is nagy gondot fordítunk. Ezért bővítjük például idén a Terézvárosi Értelmi Fogyatékosok Napközi Otthonát, az energiatakarékosság jegyében pedig nyílászárókat cserélünk a Terézvárosi Gondozó Szolgálat Benczúr utcai irodájában. Indul az időstaxi: a 60 évnél idősebb terézvárosiak ingyen vehetik igénybe az önkormányzat minibuszát, hogy könnyebben elérjék az egészségügyi intézményeket, a hivatalokat, vagy éppen segítséget kapjanak nagyobb bevásárláskor, bentlakásos szociális intézménybe történő költözéskor. | G27: ❤️ Gondoskodás, 🚦 Közlekedés
B28: 2023 | C28: 2023-9.jpg | D28: 2023.mp4 | E28: Közösségépítő programok | F28: Hiszünk a helyi rendezvények közösségépítő erejében. Hisszük, még otthonosabbá válhat a kerület, ha alkalmat adunk arra, hogy az egymást legfeljebb arcról ismerő szomszédok bemutatkozzanak egymásnak. Soha nem látott mennyiségű és minőségű kulturális rendezvénnyel járulunk hozzá ehhez: sok más mellett idén is lesz TeFeszt, Király-nap, Hunyadi téri programsorozat - például szabadtéri kiállításokkal, kertmozival -, lommentő piac, és természetesen az Eötvös10 programjai, díjmentes tanfolyamai is remek lehetőséget kínálnak ismeretségek, barátságok kötésére. Számos programunk ráadásul ingyenes vagy kedvezménnyel látogatható, mert nem szeretnénk falak közé zárni a kultúrát. Inkább kihozzuk az utcára. | G28: 🎉 Közösség
